from utils.exception import handle_exception
